[2023-04-02T03:11:12.273+0000] {taskinstance.py:1084} INFO - Dependencies all met for dep_context=non-requeueable deps ti=<TaskInstance: demo_dag.upload_data_to_mongodb manual__2023-04-02T03:11:08.386534+00:00 [queued]>
[2023-04-02T03:11:12.280+0000] {taskinstance.py:1084} INFO - Dependencies all met for dep_context=requeueable deps ti=<TaskInstance: demo_dag.upload_data_to_mongodb manual__2023-04-02T03:11:08.386534+00:00 [queued]>
[2023-04-02T03:11:12.280+0000] {taskinstance.py:1282} INFO - 
--------------------------------------------------------------------------------
[2023-04-02T03:11:12.281+0000] {taskinstance.py:1283} INFO - Starting attempt 1 of 1
[2023-04-02T03:11:12.281+0000] {taskinstance.py:1284} INFO - 
--------------------------------------------------------------------------------
[2023-04-02T03:11:12.290+0000] {taskinstance.py:1303} INFO - Executing <Task(_PythonDecoratedOperator): upload_data_to_mongodb> on 2023-04-02 03:11:08.386534+00:00
[2023-04-02T03:11:12.297+0000] {standard_task_runner.py:55} INFO - Started process 791 to run task
[2023-04-02T03:11:12.303+0000] {standard_task_runner.py:82} INFO - Running: ['***', 'tasks', 'run', 'demo_dag', 'upload_data_to_mongodb', 'manual__2023-04-02T03:11:08.386534+00:00', '--job-id', '421', '--raw', '--subdir', 'DAGS_FOLDER/test_dag.py', '--cfg-path', '/tmp/tmp9chiunwh']
[2023-04-02T03:11:12.304+0000] {standard_task_runner.py:83} INFO - Job 421: Subtask upload_data_to_mongodb
[2023-04-02T03:11:12.395+0000] {task_command.py:388} INFO - Running <TaskInstance: demo_dag.upload_data_to_mongodb manual__2023-04-02T03:11:08.386534+00:00 [running]> on host 0b6a9b63e384
[2023-04-02T03:11:12.562+0000] {taskinstance.py:1511} INFO - Exporting the following env vars:
AIRFLOW_CTX_DAG_OWNER=***
AIRFLOW_CTX_DAG_ID=demo_dag
AIRFLOW_CTX_TASK_ID=upload_data_to_mongodb
AIRFLOW_CTX_EXECUTION_DATE=2023-04-02T03:11:08.386534+00:00
AIRFLOW_CTX_TRY_NUMBER=1
AIRFLOW_CTX_DAG_RUN_ID=manual__2023-04-02T03:11:08.386534+00:00
[2023-04-02T03:11:12.810+0000] {taskinstance.py:1775} ERROR - Task failed with exception
Traceback (most recent call last):
  File "/home/airflow/.local/lib/python3.7/site-packages/airflow/decorators/base.py", line 217, in execute
    return_value = super().execute(context)
  File "/home/airflow/.local/lib/python3.7/site-packages/airflow/operators/python.py", line 175, in execute
    return_value = self.execute_callable()
  File "/home/airflow/.local/lib/python3.7/site-packages/airflow/operators/python.py", line 192, in execute_callable
    return self.python_callable(*self.op_args, **self.op_kwargs)
  File "/opt/airflow/dags/test_dag.py", line 42, in upload_data_to_mongodb
    coll.insert_many(json_response['response'])
KeyError: 'response'
[2023-04-02T03:11:12.864+0000] {taskinstance.py:1326} INFO - Marking task as FAILED. dag_id=demo_dag, task_id=upload_data_to_mongodb, execution_date=20230402T031108, start_date=20230402T031112, end_date=20230402T031112
[2023-04-02T03:11:12.914+0000] {standard_task_runner.py:105} ERROR - Failed to execute job 421 for task upload_data_to_mongodb ('response'; 791)
[2023-04-02T03:11:13.006+0000] {local_task_job.py:212} INFO - Task exited with return code 1
[2023-04-02T03:11:13.049+0000] {taskinstance.py:2585} INFO - 0 downstream tasks scheduled from follow-on schedule check
