[2023-04-04T02:52:48.864+0000] {taskinstance.py:1084} INFO - Dependencies all met for dep_context=non-requeueable deps ti=<TaskInstance: demo_dag2.upload_to_azure_sql manual__2023-04-04T02:52:31.253574+00:00 [queued]>
[2023-04-04T02:52:48.896+0000] {taskinstance.py:1084} INFO - Dependencies all met for dep_context=requeueable deps ti=<TaskInstance: demo_dag2.upload_to_azure_sql manual__2023-04-04T02:52:31.253574+00:00 [queued]>
[2023-04-04T02:52:48.897+0000] {taskinstance.py:1282} INFO - 
--------------------------------------------------------------------------------
[2023-04-04T02:52:48.897+0000] {taskinstance.py:1283} INFO - Starting attempt 1 of 1
[2023-04-04T02:52:48.898+0000] {taskinstance.py:1284} INFO - 
--------------------------------------------------------------------------------
[2023-04-04T02:52:48.946+0000] {taskinstance.py:1303} INFO - Executing <Task(_PythonDecoratedOperator): upload_to_azure_sql> on 2023-04-04 02:52:31.253574+00:00
[2023-04-04T02:52:48.967+0000] {standard_task_runner.py:55} INFO - Started process 154 to run task
[2023-04-04T02:52:48.981+0000] {standard_task_runner.py:82} INFO - Running: ['***', 'tasks', 'run', 'demo_dag2', 'upload_to_azure_sql', 'manual__2023-04-04T02:52:31.253574+00:00', '--job-id', '449', '--raw', '--subdir', 'DAGS_FOLDER/test_dag2.py', '--cfg-path', '/tmp/tmp6rpb4oxl']
[2023-04-04T02:52:48.982+0000] {standard_task_runner.py:83} INFO - Job 449: Subtask upload_to_azure_sql
[2023-04-04T02:52:49.127+0000] {task_command.py:388} INFO - Running <TaskInstance: demo_dag2.upload_to_azure_sql manual__2023-04-04T02:52:31.253574+00:00 [running]> on host dadb51b41a46
[2023-04-04T02:52:49.227+0000] {taskinstance.py:1511} INFO - Exporting the following env vars:
AIRFLOW_CTX_DAG_OWNER=***
AIRFLOW_CTX_DAG_ID=demo_dag2
AIRFLOW_CTX_TASK_ID=upload_to_azure_sql
AIRFLOW_CTX_EXECUTION_DATE=2023-04-04T02:52:31.253574+00:00
AIRFLOW_CTX_TRY_NUMBER=1
AIRFLOW_CTX_DAG_RUN_ID=manual__2023-04-04T02:52:31.253574+00:00
[2023-04-04T02:52:49.245+0000] {taskinstance.py:1775} ERROR - Task failed with exception
Traceback (most recent call last):
  File "/home/airflow/.local/lib/python3.7/site-packages/airflow/decorators/base.py", line 217, in execute
    return_value = super().execute(context)
  File "/home/airflow/.local/lib/python3.7/site-packages/airflow/operators/python.py", line 175, in execute
    return_value = self.execute_callable()
  File "/home/airflow/.local/lib/python3.7/site-packages/airflow/operators/python.py", line 192, in execute_callable
    return self.python_callable(*self.op_args, **self.op_kwargs)
  File "/opt/airflow/dags/test_dag2.py", line 51, in upload_to_azure_sql
    'DRIVER={Devart ODBC Driver for SQLAzure};Server=tcp:cs779-server.database.windows.net,1433;Database=cs779;Uid=epoch;Pwd=**********;Encrypt=yes;TrustServerCertificate=no;Connection Timeout=30;'
pyodbc.Error: ('01000', "[01000] [unixODBC][Driver Manager]Can't open lib 'Devart ODBC Driver for SQLAzure' : file not found (0) (SQLDriverConnect)")
[2023-04-04T02:52:49.266+0000] {taskinstance.py:1326} INFO - Marking task as FAILED. dag_id=demo_dag2, task_id=upload_to_azure_sql, execution_date=20230404T025231, start_date=20230404T025248, end_date=20230404T025249
[2023-04-04T02:52:49.280+0000] {standard_task_runner.py:105} ERROR - Failed to execute job 449 for task upload_to_azure_sql (('01000', "[01000] [unixODBC][Driver Manager]Can't open lib 'Devart ODBC Driver for SQLAzure' : file not found (0) (SQLDriverConnect)"); 154)
[2023-04-04T02:52:49.327+0000] {local_task_job.py:212} INFO - Task exited with return code 1
[2023-04-04T02:52:49.365+0000] {taskinstance.py:2585} INFO - 0 downstream tasks scheduled from follow-on schedule check
